Workbook

Sheet Cover
B2: CircularEnergies
B3: ENERGY TRANSITION FEASIBILITY & INTELLIGENCE
B6: ILLUSTRATIVE PROJECT FINANCE MODEL
B7: Kano Agro-Industrial Solar-plus-Storage Project
B8: 5.0 MWp Solar PV + 4.0 MWh Battery Storage · Commercial & Industrial PPA · Kano State, Nigeria
B10: SAMPLE DELIVERABLE - NOT A LIVE CLIENT ENGAGEMENT
B11: This model has been prepared by CircularEnergies Ltd as an illustrative sample of deliverable standard and methodology. The project, sponsor and offtaker are hypothetical. Assumptions are representative of current Nigerian C&I solar market conditions but do not relate to any actual transaction. No reliance should be placed on the outputs for investment purposes.
B13: Model structure
B14: Assumptions - All model inputs. Blue cells are hardcoded inputs; nothing else requires editing.
B15: Model - Generation, revenue, operating costs, capital allowances and taxation.
B16: Debt - Funding sources, debt sizing, sculpted repayment profile and reserve account.
B17: Financials - Income statement, cash flow statement and balance sheet.
... B26: Prepared by Zayyad Yusuf Aliyu, Founder & Principal Analyst · info@circularenergies.africa · +234 815 824 2934

Sheet Assumptions
B2: CircularEnergies
B3: ASSUMPTIONS
B4: Blue cells are inputs. All other values are calculated.
B6: PROJECT IDENTITY
B7: Project name | D7: Kano Agro-Industrial Solar-plus-Storage Project
B8: Project company (SPV) | D8: Sahel Solar Power SPV Ltd (illustrative)
B9: Offtaker | D9: Northern Grains Processing Ltd (illustrative)
B10: Location | D10: Kano State, Nigeria
B11: Model currency | D11: USD
B13: TECHNICAL
B14: Solar capacity | C14: MWp | D14: 5
B15: Battery energy capacity | C15: MWh | D15: 4
B16: Specific yield | C16: kWh/kWp/yr | D16: 1750 | E16: Kano site, P50 basis
B17: Plant availability | C17: % | D17: 0.97
B18: System & storage round-trip losses | C18: % | D18: 0.03
B19: Annual degradation | C19: %/yr | D19: 0.0055
B20: Operating life | C20: years | D20: 20
B22: CAPITAL COST
B23: Solar EPC (supply & install) | C23: USD | D23: 3400000
B24: Battery system (supply & install) | C24: USD | D24: 1150000
B25: Grid connection & interconnection | C25: USD | D25: 180000
B26: Civil works & site preparation | C26: USD | D26: 260000
B27: Development costs to financial close | C27: USD | D27: 145000
B28: Owner's costs & project management | C28: USD | D28: 175000
B29: Contingency | C29: % of above | D29: 0.05
B30: Total base capital cost | C30: USD | D30: =SUM(D23:D28)*(1+D29) -> 5575500
B32: REVENUE & OFFTAKE
B33: PPA tariff | C33: USD/MWh | D33: 145 | E33: vs displaced diesel c. USD 380/MWh
B34: Tariff escalation | C34: %/yr | D34: 0.02 | E34: USD-indexed
B35: Contracted annual volume | C35: MWh | D35: 9000 | E35: Offtaker load exceeds plant output
B36: Take-or-pay minimum | C36: % of contract | D36: 0.85
B37: Contract tenor | C37: years | D37: 15
B39: OPERATING COSTS
B40: O&M contract | C40: % of plant EPC | D40: 0.014
B41: O&M cost | C41: USD/yr | D41: =(D23+D24)*D40 -> 63700
B42: Insurance | C42: % of capex | D42: 0.0055
B43: Insurance cost | C43: USD/yr | D43: =D30*D42 -> 30665.25
B44: Land lease | C44: USD/yr | D44: 12000
B45: Security & site services | C45: USD/yr | D45: 22000
B46: Administration, audit & SPV costs | C46: USD/yr | D46: 34000
...

Sheet Model
B2: CircularEnergies
B3: OPERATING MODEL
B4: Generation, revenue, operating costs, capital allowances and tax
B6: Period | D6: Construction | E6: Yr 1 | F6: Yr 2 | G6: Yr 3 | H6: Yr 4 | I6: Yr 5 | J6: Yr 6 | K6: Yr 7 | L6: Yr 8 | M6: Yr 9 | N6: Yr 10 | O6: Yr 11 | P6: Yr 12 | Q6: Yr 13 | R6: Yr 14 | S6: Yr 15 | T6: Yr 16 | U6: Yr 17 | V6: Yr 18 | W6: Yr 19 | X6: Yr 20
B8: GENERATION
B9: Gross generation | C9: MWh | E9: =Assumptions!$D$14*Assumptions!$D$16*(1-Assumptions!$D$19)^(1-1) -> 8750 | F9: =Assumptions!$D$14*Assumptions!$D$16*(1-Assumptions!$D$19)^(2-1) -> 8701.875 | G9: =Assumptions!$D$14*Assumptions!$D$16*(1-Assumptions!$D$19)^(3-1) -> 8654.0147 | H9: =Assumptions!$D$14*Assumptions!$D$16*(1-Assumptions!$D$19)^(4-1) -> 8606.4176 | I9: =Assumptions!$D$14*Assumptions!$D$16*(1-Assumptions!$D$19)^(5-1) -> 8559.0823 | J9: =Assumptions!$D$14*Assumptions!$D$16*(1-Assumptions!$D$19)^(6-1) -> 8512.0074 | K9: =Assumptions!$D$14*Assumptions!$D$16*(1-Assumptions!$D$19)^(7-1) -> 8465.1913 | L9: =Assumptions!$D$14*Assumptions!$D$16*(1-Assumptions!$D$19)^(8-1) -> 8418.6328 | M9: =Assumptions!$D$14*Assumptions!$D$16*(1-Assumptions!$D$19)^(9-1) -> 8372.3303 | N9: =Assumptions!$D$14*Assumptions!$D$16*(1-Assumptions!$D$19)^(10-1) -> 8326.2825 | O9: =Assumptions!$D$14*Assumptions!$D$16*(1-Assumptions!$D$19)^(11-1) -> 8280.4879 | P9: =Assumptions!$D$14*Assumptions!$D$16*(1-Assumptions!$D$19)^(12-1) -> 8234.9452 | Q9: =Assumptions!$D$14*Assumptions!$D$16*(1-Assumptions!$D$19)^(13-1) -> 8189.653 | R9: =Assumptions!$D$14*Assumptions!$D$16*(1-Assumptions!$D$19)^(14-1) -> 8144.6099 | S9: =Assumptions!$D$14*Assumptions!$D$16*(1-Assumptions!$D$19)^(15-1) -> 8099.8146 | T9: =Assumptions!$D$14*Assumptions!$D$16*(1-Assumptions!$D$19)^(16-1) -> 8055.2656 | U9: =Assumptions!$D$14*Assumptions!$D$16*(1-Assumptions!$D$19)^(17-1) -> 8010.9616 | V9: =Assumptions!$D$14*Assumptions!$D$16*(1-Assumptions!$D$19)^(18-1) -> 7966.9014 | W9: =Assumptions!$D$14*Assumptions!$D$16*(1-Assumptions!$D$19)^(19-1) -> 7923.0834 | X9: =Assumptions!$D$14*Assumptions!$D$16*(1-Assumptions!$D$19)^(20-1) -> 7879.5064
B10: Net delivered energy | C10: MWh | E10: =E9*Assumptions!$D$17*(1-Assumptions!$D$18) -> 8232.875 | F10: =F9*Assumptions!$D$17*(1-Assumptions!$D$18) -> 8187.5942 | G10: =G9*Assumptions!$D$17*(1-Assumptions!$D$18) -> 8142.5624 | H10: =H9*Assumptions!$D$17*(1-Assumptions!$D$18) -> 8097.7783 | I10: =I9*Assumptions!$D$17*(1-Assumptions!$D$18) -> 8053.2405 | J10: =J9*Assumptions!$D$17*(1-Assumptions!$D$18) -> 8008.9477 | K10: =K9*Assumptions!$D$17*(1-Assumptions!$D$18) -> 7964.8985 | L10: =L9*Assumptions!$D$17*(1-Assumptions!$D$18) -> 7921.0916 | ... X10: =X9*Assumptions!$D$17*(1-Assumptions!$D$18) -> 7413.8276
B11: Billable volume | C11: MWh | E11: =MAX(MIN(E10,Assumptions!$D$35),Assumptions!$D$35*Assumptions!$D$36) -> 8232.875 | F11: =MAX(MIN(F10,Assumptions!$D$35),Assumptions!$D$35*Assumptions!$D$36) -> 8187.5942 | G11: =MAX(MIN(G10,Assumptions!$D$35),Assumptions!$D$35*Assumptions!$D$36) -> 8142.5624 | H11: =MAX(MIN(H10,Assumptions!$D$35),Assumptions!$D$35*Assumptions!$D$36) -> 8097.7783 | I11: =MAX(MIN(I10,Assumptions!$D$35),Assumptions!$D$35*Assumptions!$D$36) -> 8053.2405 | J11: =MAX(MIN(J10,Assumptions!$D$35),Assumptions!$D$35*Assumptions!$D$36) -> 8008.9477 | K11: =MAX(MIN(K10,Assumptions!$D$35),Assumptions!$D$35*Assumptions!$D$36) -> 7964.8985 | L11: =MAX(MIN(L10,Assumptions!$D$35),Assumptions!$D$35*Assumptions!$D$36) -> 7921.0916 | ... X11: =MAX(MIN(X10,Assumptions!$D$35),Assumptions!$D$35*Assumptions!$D$36) -> 7650
B13: REVENUE
B14: Tariff | C14: USD/MWh | E14: =Assumptions!$D$33*(1+Assumptions!$D$34)^(1-1) -> 145 | F14: =Assumptions!$D$33*(1+Assumptions!$D$34)^(2-1) -> 147.9 | G14: =Assumptions!$D$33*(1+Assumptions!$D$34)^(3-1) -> 150.858 | H14: =Assumptions!$D$33*(1+Assumptions!$D$34)^(4-1) -> 153.87516 | I14: =Assumptions!$D$33*(1+Assumptions!$D$34)^(5-1) -> 156.95266 | J14: =Assumptions!$D$33*(1+Assumptions!$D$34)^(6-1) -> 160.09172 | K14: =Assumptions!$D$33*(1+Assumptions!$D$34)^(7-1) -> 163.29355 | L14: =Assumptions!$D$33*(1+Assumptions!$D$34)^(8-1) -> 166.55942 | M14: =Assumptions!$D$33*(1+Assumptions!$D$34)^(9-1) -> 169.89061 | N14: =Assumptions!$D$33*(1+Assumptions!$D$34)^(10-1) -> 173.28842 | O14: =Assumptions!$D$33*(1+Assumptions!$D$34)^(11-1) -> 176.75419 | P14: =Assumptions!$D$33*(1+Assumptions!$D$34)^(12-1) -> 180.28927 | Q14: =Assumptions!$D$33*(1+Assumptions!$D$34)^(13-1) -> 183.89506 | R14: =Assumptions!$D$33*(1+Assumptions!$D$34)^(14-1) -> 187.57296 | S14: =Assumptions!$D$33*(1+Assumptions!$D$34)^(15-1) -> 191.32442 | T14: =Assumptions!$D$33*(1+Assumptions!$D$34)^(16-1) -> 195.15091 | U14: =Assumptions!$D$33*(1+Assumptions!$D$34)^(17-1) -> 199.05393 | V14: =Assumptions!$D$33*(1+Assumptions!$D$34)^(18-1) -> 203.03501 | W14: =Assumptions!$D$33*(1+Assumptions!$D$34)^(19-1) -> 207.09571 | X14: =Assumptions!$D$33*(1+Assumptions!$D$34)^(20-1) -> 211.23762
B15: Contract revenue | C15: USD | E15: =E11*E14 -> 1193766.9 | F15: =F11*F14 -> 1210945.2 | G15: =G11*G14 -> 1228370.7 | H15: =H11*H14 -> 1246046.9 | I15: =I11*I14 -> 1263977.6 | J15: =J11*J14 -> 1282166.2 | K15: =K11*K14 -> 1300616.6 | L15: =L11*L14 -> 1319332.4 | ... X15: =X11*X14 -> 1615967.8
B17: OPERATING COSTS
B18: Total operating costs | C18: USD | E18: =-Assumptions!$D$48*(1+Assumptions!$D$49)^(1-1) -> -180365.25 | F18: =-Assumptions!$D$48*(1+Assumptions!$D$49)^(2-1) -> -186678.03 | G18: =-Assumptions!$D$48*(1+Assumptions!$D$49)^(3-1) -> -193211.76 | H18: =-Assumptions!$D$48*(1+Assumptions!$D$49)^(4-1) -> -199974.18 | I18: =-Assumptions!$D$48*(1+Assumptions!$D$49)^(5-1) -> -206973.27 | J18: =-Assumptions!$D$48*(1+Assumptions!$D$49)^(6-1) -> -214217.34 | K18: =-Assumptions!$D$48*(1+Assumptions!$D$49)^(7-1) -> -221714.94 | L18: =-Assumptions!$D$48*(1+Assumptions!$D$49)^(8-1) -> -229474.97 | M18: =-Assumptions!$D$48*(1+Assumptions!$D$49)^(9-1) -> -237506.59 | N18: =-Assumptions!$D$48*(1+Assumptions!$D$49)^(10-1) -> -245819.32 | O18: =-Assumptions!$D$48*(1+Assumptions!$D$49)^(11-1) -> -254423 | P18: =-Assumptions!$D$48*(1+Assumptions!$D$49)^(12-1) -> -263327.8 | Q18: =-Assumptions!$D$48*(1+Assumptions!$D$49)^(13-1) -> -272544.28 | R18: =-Assumptions!$D$48*(1+Assumptions!$D$49)^(14-1) -> -282083.33 | S18: =-Assumptions!$D$48*(1+Assumptions!$D$49)^(15-1) -> -291956.24 | T18: =-Assumptions!$D$48*(1+Assumptions!$D$49)^(16-1) -> -302174.71 | U18: =-Assumptions!$D$48*(1+Assumptions!$D$49)^(17-1) -> -312750.83 | V18: =-Assumptions!$D$48*(1+Assumptions!$D$49)^(18-1) -> -323697.1 | W18: =-Assumptions!$D$48*(1+Assumptions!$D$49)^(19-1) -> -335026.5 | X18: =-Assumptions!$D$48*(1+Assumptions!$D$49)^(20-1) -> -346752.43
B19: EBITDA | C19: USD | E19: =E15+E18 -> 1013401.6 | F19: =F15+F18 -> 1024267.1 | G19: =G15+G18 -> 1035158.9 | H19: =H15+H18 -> 1046072.8 | I19: =I15+I18 -> 1057004.3 | J19: =J15+J18 -> 1067948.9 | K19: =K15+K18 -> 1078901.6 | L19: =L15+L18 -> 1089857.5 | ... X19: =X15+X18 -> 1269215.4
B20: EBITDA margin | C20: % | E20: =IFERROR(E19/E15,0) -> 0.84891083 | F20: =IFERROR(F19/F15,0) -> 0.84584105 | G20: =IFERROR(G19/G15,0) -> 0.84270891 | H20: =IFERROR(H19/H15,0) -> 0.83951313 | I20: =IFERROR(I19/I15,0) -> 0.83625241 | J20: =IFERROR(J19/J15,0) -> 0.83292545 | K20: =IFERROR(K19/K15,0) -> 0.82953089 | L20: =IFERROR(L19/L15,0) -> 0.82606736 | ... X20: =IFERROR(X19/X15,0) -> 0.7854212
B22: CAPITAL ALLOWANCES & TAXATION
B23: Qualifying capital expenditure | C23: USD | D23: =Assumptions!$D$30+Debt!$D$8 -> 5750291.9
B24: Capital allowance pool - opening | C24: USD | E24: =$D$23 -> 5750291.9 | F24: =E26 -> 5750291.9 | G24: =F26 -> 5750291.9 | H24: =G26 -> 5750291.9 | I24: =H26 -> 1437573 | J24: =I26 -> 0 | K24: =J26 -> 0 | L24: =K26 -> 0 | M24: =L26 -> 0 | ... X24: =W26 -> 0
B25: Capital allowance claimed | C25: USD | E25: =IF(E27=1,0,MIN(E24,IF(1=Assumptions!$D$64+1,$D$23*(Assumptions!$D$65+Assumptions!$D$66),$D$23*Assumptions!$D$66))) -> 0 | F25: =IF(F27=1,0,MIN(F24,IF(2=Assumptions!$D$64+1,$D$23*(Assumptions!$D$65+Assumptions!$D$66),$D$23*Assumptions!$D$66))) -> 0 | G25: =IF(G27=1,0,MIN(G24,IF(3=Assumptions!$D$64+1,$D$23*(Assumptions!$D$65+Assumptions!$D$66),$D$23*Assumptions!$D$66))) -> 0 | H25: =IF(H27=1,0,MIN(H24,IF(4=Assumptions!$D$64+1,$D$23*(Assumptions!$D$65+Assumptions!$D$66),$D$23*Assumptions!$D$66))) -> 4312718.9 | I25: =IF(I27=1,0,MIN(I24,IF(5=Assumptions!$D$64+1,$D$23*(Assumptions!$D$65+Assumptions!$D$66),$D$23*Assumptions!$D$66))) -> 1437573 | J25: =IF(J27=1,0,MIN(J24,IF(6=Assumptions!$D$64+1,$D$23*(Assumptions!$D$65+Assumptions!$D$66),$D$23*Assumptions!$D$66))) -> 0 | K25: =IF(K27=1,0,MIN(K24,IF(7=Assumptions!$D$64+1,$D$23*(Assumptions!$D$65+Assumptions!$D$66),$D$23*Assumptions!$D$66))) -> 0 | L25: =IF(L27=1,0,MIN(L24,IF(8=Assumptions!$D$64+1,$D$23*(Assumptions!$D$65+Assumptions!$D$66),$D$23*Assumptions!$D$66))) -> 0 | M25: =IF(M27=1,0,MIN(M24,IF(9=Assumptions!$D$64+1,$D$23*(Assumptions!$D$65+Assumptions!$D$66),$D$23*Assumptions!$D$66))) -> 0 | N25: =IF(N27=1,0,MIN(N24,IF(10=Assumptions!$D$64+1,$D$23*(Assumptions!$D$65+Assumptions!$D$66),$D$23*Assumptions!$D$66))) -> 0 | O25: =IF(O27=1,0,MIN(O24,IF(11=Assumptions!$D$64+1,$D$23*(Assumptions!$D$65+Assumptions!$D$66),$D$23*Assumptions!$D$66))) -> 0 | P25: =IF(P27=1,0,MIN(P24,IF(12=Assumptions!$D$64+1,$D$23*(Assumptions!$D$65+Assumptions!$D$66),$D$23*Assumptions!$D$66))) -> 0 | Q25: =IF(Q27=1,0,MIN(Q24,IF(13=Assumptions!$D$64+1,$D$23*(Assumptions!$D$65+Assumptions!$D$66),$D$23*Assumptions!$D$66))) -> 0 | R25: =IF(R27=1,0,MIN(R24,IF(14=Assumptions!$D$64+1,$D$23*(Assumptions!$D$65+Assumptions!$D$66),$D$23*Assumptions!$D$66))) -> 0 | S25: =IF(S27=1,0,MIN(S24,IF(15=Assumptions!$D$64+1,$D$23*(Assumptions!$D$65+Assumptions!$D$66),$D$23*Assumptions!$D$66))) -> 0 | T25: =IF(T27=1,0,MIN(T24,IF(16=Assumptions!$D$64+1,$D$23*(Assumptions!$D$65+Assumptions!$D$66),$D$23*Assumptions!$D$66))) -> 0 | U25: =IF(U27=1,0,MIN(U24,IF(17=Assumptions!$D$64+1,$D$23*(Assumptions!$D$65+Assumptions!$D$66),$D$23*Assumptions!$D$66))) -> 0 | V25: =IF(V27=1,0,MIN(V24,IF(18=Assumptions!$D$64+1,$D$23*(Assumptions!$D$65+Assumptions!$D$66),$D$23*Assumptions!$D$66))) -> 0 | W25: =IF(W27=1,0,MIN(W24,IF(19=Assumptions!$D$64+1,$D$23*(Assumptions!$D$65+Assumptions!$D$66),$D$23*Assumptions!$D$66))) -> 0 | X25: =IF(X27=1,0,MIN(X24,IF(20=Assumptions!$D$64+1,$D$23*(Assumptions!$D$65+Assumptions!$D$66),$D$23*Assumptions!$D$66))) -> 0
B26: Capital allowance pool - closing | C26: USD | E26: =E24-E25 -> 5750291.9 | F26: =F24-F25 -> 5750291.9 | G26: =G24-G25 -> 5750291.9 | H26: =H24-H25 -> 1437573 | I26: =I24-I25 -> 0 | J26: =J24-J25 -> 0 | K26: =K24-K25 -> 0 | L26: =L24-L25 -> 0 | ... X26: =X24-X25 -> 0
B27: Pioneer relief in force | C27: 1 = yes | E27: =IF(1<=Assumptions!$D$64,1,0) -> 1 | F27: =IF(2<=Assumptions!$D$64,1,0) -> 1 | G27: =IF(3<=Assumptions!$D$64,1,0) -> 1 | H27: =IF(4<=Assumptions!$D$64,1,0) -> 0 | I27: =IF(5<=Assumptions!$D$64,1,0) -> 0 | J27: =IF(6<=Assumptions!$D$64,1,0) -> 0 | K27: =IF(7<=Assumptions!$D$64,1,0) -> 0 | L27: =IF(8<=Assumptions!$D$64,1,0) -> 0 | M27: =IF(9<=Assumptions!$D$64,1,0) -> 0 | N27: =IF(10<=Assumptions!$D$64,1,0) -> 0 | O27: =IF(11<=Assumptions!$D$64,1,0) -> 0 | P27: =IF(12<=Assumptions!$D$64,1,0) -> 0 | Q27: =IF(13<=Assumptions!$D$64,1,0) -> 0 | R27: =IF(14<=Assumptions!$D$64,1,0) -> 0 | S27: =IF(15<=Assumptions!$D$64,1,0) -> 0 | T27: =IF(16<=Assumptions!$D$64,1,0) -> 0 | U27: =IF(17<=Assumptions!$D$64,1,0) -> 0 | V27: =IF(18<=Assumptions!$D$64,1,0) -> 0 | W27: =IF(19<=Assumptions!$D$64,1,0) -> 0 | X27: =IF(20<=Assumptions!$D$64,1,0) -> 0
B28: Assessable profit | C28: USD | E28: =IF(E27=1,0,MAX(0,E19-Debt!E29-E25)) -> 0 | F28: =IF(F27=1,0,MAX(0,F19-Debt!F29-F25)) -> 0 | G28: =IF(G27=1,0,MAX(0,G19-Debt!G29-G25)) -> 0 | H28: =IF(H27=1,0,MAX(0,H19-Debt!H29-H25)) -> 0 | I28: =IF(I27=1,0,MAX(0,I19-Debt!I29-I25)) -> 0 | J28: =IF(J27=1,0,MAX(0,J19-Debt!J29-J25)) -> 787431.21 | K28: =IF(K27=1,0,MAX(0,K19-Debt!K29-K25)) -> 817872.14 | L28: =IF(L27=1,0,MAX(0,L19-Debt!L29-L25)) -> 850640.7 | ... X28: =IF(X27=1,0,MAX(0,X19-Debt!X29-X25)) -> 1269215.4
B29: Taxation | C29: USD | E29: =-E28*(Assumptions!$D$62+Assumptions!$D$63) -> 0 | F29: =-F28*(Assumptions!$D$62+Assumptions!$D$63) -> 0 | G29: =-G28*(Assumptions!$D$62+Assumptions!$D$63) -> 0 | H29: =-H28*(Assumptions!$D$62+Assumptions!$D$63) -> 0 | I29: =-I28*(Assumptions!$D$62+Assumptions!$D$63) -> 0 | J29: =-J28*(Assumptions!$D$62+Assumptions!$D$63) -> -259852.3 | K29: =-K28*(Assumptions!$D$62+Assumptions!$D$63) -> -269897.81 | L29: =-L28*(Assumptions!$D$62+Assumptions!$D$63) -> -280711.43 | ... X29: =-X28*(Assumptions!$D$62+Assumptions!$D$63) -> -418841.07
B31: CASH FLOW AVAILABLE FOR DEBT SERVICE
B32: CFADS (post-tax) | C32: USD | E32: =E19+E29 -> 1013401.6 | F32: =F19+F29 -> 1024267.1 | G32: =G19+G29 -> 1035158.9 | H32: =H19+H29 -> 1046072.8 | I32: =I19+I29 -> 1057004.3 | J32: =J19+J29 -> 808096.55 | K32: =K19+K29 -> 809003.81 | L32: =L19+L29 -> 809146.03 | ... X32: =X19+X29 -> 850374.29

Sheet Debt
B2: CircularEnergies
B3: FUNDING & DEBT
B4: Sources and uses, debt sizing, sculpted repayment and reserve account
B6: Period | D6: Construction | E6: Yr 1 | F6: Yr 2 | G6: Yr 3 | H6: Yr 4 | I6: Yr 5 | J6: Yr 6 | K6: Yr 7 | L6: Yr 8 | M6: Yr 9 | N6: Yr 10 | O6: Yr 11 | P6: Yr 12 | Q6: Yr 13 | R6: Yr 14 | S6: Yr 15 | T6: Yr 16 | U6: Yr 17 | V6: Yr 18 | W6: Yr 19 | X6: Yr 20
B7: Base capital cost | C7: USD | D7: =Assumptions!$D$30 -> 5575500
B8: Interest during construction | C8: USD | D8: =D7*Assumptions!$D$52*Assumptions!$D$53*Assumptions!$D$58*0.5 -> 174791.92
B9: Arrangement & upfront fees | C9: USD | D9: =D7*Assumptions!$D$52*Assumptions!$D$56 -> 55197.45
B10: Debt service reserve account | C10: USD | D10: =E30*Assumptions!$D$57/12 -> 230425.25
B11: Minimum cash balance | C11: USD | D11: =Assumptions!$D$59 -> 50000
B12: Total funding requirement | C12: USD | D12: =SUM(D7:D11) -> 6085914.6
B14: Senior debt | C14: USD | D14: =Assumptions!$D$30*Assumptions!$D$52 -> 3679830
B15: Sponsor equity | C15: USD | D15: =D12-D14 -> 2406084.6
B16: Total sources | C16: USD | D16: =D14+D15 -> 6085914.6
B18: Effective gearing (of total funding) | C18: % | D18: =D14/D16 -> 0.604647
B20: DEBT SIZING — SCULPTED TO OPERATING CASH FLOW
B21: Sculpting basis (EBITDA) | C21: USD | E21: =IF(1<=Assumptions!$D$54,Model!E19,0) -> 1013401.6 | F21: =IF(2<=Assumptions!$D$54,Model!F19,0) -> 1024267.1 | G21: =IF(3<=Assumptions!$D$54,Model!G19,0) -> 1035158.9 | H21: =IF(4<=Assumptions!$D$54,Model!H19,0) -> 1046072.8 | I21: =IF(5<=Assumptions!$D$54,Model!I19,0) -> 1057004.3 | J21: =IF(6<=Assumptions!$D$54,Model!J19,0) -> 1067948.9 | K21: =IF(7<=Assumptions!$D$54,Model!K19,0) -> 1078901.6 | L21: =IF(8<=Assumptions!$D$54,Model!L19,0) -> 1089857.5 | M21: =IF(9<=Assumptions!$D$54,Model!M19,0) -> 1100811 | N21: =IF(10<=Assumptions!$D$54,Model!N19,0) -> 1111756.7 | O21: =IF(11<=Assumptions!$D$54,Model!O19,0) -> 1122688.5 | P21: =IF(12<=Assumptions!$D$54,Model!P19,0) -> 1133600.4 | Q21: =IF(13<=Assumptions!$D$54,Model!Q19,0) -> 1144485.7 | R21: =IF(14<=Assumptions!$D$54,Model!R19,0) -> 1155337.7 | S21: =IF(15<=Assumptions!$D$54,Model!S19,0) -> 0 | T21: =IF(16<=Assumptions!$D$54,Model!T19,0) -> 0 | U21: =IF(17<=Assumptions!$D$54,Model!U19,0) -> 0 | V21: =IF(18<=Assumptions!$D$54,Model!V19,0) -> 0 | W21: =IF(19<=Assumptions!$D$54,Model!W19,0) -> 0 | X21: =IF(20<=Assumptions!$D$54,Model!X19,0) -> 0
B22: Discount factor at cost of debt | C22: x | E22: =IF(1<=Assumptions!$D$54,1/(1+Assumptions!$D$53)^1,0) -> 0.91324201 | F22: =IF(2<=Assumptions!$D$54,1/(1+Assumptions!$D$53)^2,0) -> 0.83401097 | G22: =IF(3<=Assumptions!$D$54,1/(1+Assumptions!$D$53)^3,0) -> 0.76165385 | H22: =IF(4<=Assumptions!$D$54,1/(1+Assumptions!$D$53)^4,0) -> 0.69557429 | I22: =IF(5<=Assumptions!$D$54,1/(1+Assumptions!$D$53)^5,0) -> 0.63522767 | J22: =IF(6<=Assumptions!$D$54,1/(1+Assumptions!$D$53)^6,0) -> 0.58011659 | K22: =IF(7<=Assumptions!$D$54,1/(1+Assumptions!$D$53)^7,0) -> 0.52978684 | L22: =IF(8<=Assumptions!$D$54,1/(1+Assumptions!$D$53)^8,0) -> 0.4838236 | M22: =IF(9<=Assumptions!$D$54,1/(1+Assumptions!$D$53)^9,0) -> 0.44184803 | N22: =IF(10<=Assumptions!$D$54,1/(1+Assumptions!$D$53)^10,0) -> 0.40351419 | O22: =IF(11<=Assumptions!$D$54,1/(1+Assumptions!$D$53)^11,0) -> 0.36850611 | P22: =IF(12<=Assumptions!$D$54,1/(1+Assumptions!$D$53)^12,0) -> 0.33653526 | Q22: =IF(13<=Assumptions!$D$54,1/(1+Assumptions!$D$53)^13,0) -> 0.30733813 | R22: =IF(14<=Assumptions!$D$54,1/(1+Assumptions!$D$53)^14,0) -> 0.2806741 | S22: =IF(15<=Assumptions!$D$54,1/(1+Assumptions!$D$53)^15,0) -> 0 | T22: =IF(16<=Assumptions!$D$54,1/(1+Assumptions!$D$53)^16,0) -> 0 | U22: =IF(17<=Assumptions!$D$54,1/(1+Assumptions!$D$53)^17,0) -> 0 | V22: =IF(18<=Assumptions!$D$54,1/(1+Assumptions!$D$53)^18,0) -> 0 | W22: =IF(19<=Assumptions!$D$54,1/(1+Assumptions!$D$53)^19,0) -> 0 | X22: =IF(20<=Assumptions!$D$54,1/(1+Assumptions!$D$53)^20,0) -> 0
B23: PV of sculpting basis | C23: USD | E23: =E21*E22 -> 925480.94 | F23: =F21*F22 -> 854250.03 | G23: =G21*G22 -> 788432.78 | H23: =H21*H22 -> 727621.32 | I23: =I21*I22 -> 671438.36 | J23: =J21*J22 -> 619534.84 | K23: =K21*K22 -> 571587.88 | L23: =L21*L22 -> 527298.76 | ... X23: =X21*X22 -> 0
B24: Total PV of sculpting basis | C24: USD | D24: =SUM(E23:X23) -> 8091877.2
B25: Sculpting factor (debt / PV basis) | C25: x | D25: =D14/D24 -> 0.45475603
B27: SENIOR DEBT SCHEDULE
B28: Opening balance | C28: USD | E28: =$D$14 -> 3679830 | F28: =E32 -> 3568563.3 | G28: =F32 -> 3441785.2 | H28: =G32 -> 3298010 | I28: =H32 -> 3135613.1 | J28: =I32 -> 2952817.2 | K28: =J32 -> 2747678.7 | L28: =K32 -> 2518071.2 | M28: =L32 -> 2261668.7 | ... X28: =W32 -> 0
B29: Interest | C29: USD | E29: =E28*Assumptions!$D$53 -> 349583.85 | F29: =F28*Assumptions!$D$53 -> 339013.52 | G29: =G28*Assumptions!$D$53 -> 326969.59 | H29: =H28*Assumptions!$D$53 -> 313310.95 | I29: =I28*Assumptions!$D$53 -> 297883.24 | J29: =J28*Assumptions!$D$53 -> 280517.64 | K29: =K28*Assumptions!$D$53 -> 261029.48 | L29: =L28*Assumptions!$D$53 -> 239216.76 | ... X29: =X28*Assumptions!$D$53 -> 0
B30: Total debt service | C30: USD | E30: =IF(1<=Assumptions!$D$54,E21*$D$25,0) -> 460850.5 | F30: =IF(2<=Assumptions!$D$54,F21*$D$25,0) -> 465791.67 | G30: =IF(3<=Assumptions!$D$54,G21*$D$25,0) -> 470744.76 | H30: =IF(4<=Assumptions!$D$54,H21*$D$25,0) -> 475707.9 | I30: =IF(5<=Assumptions!$D$54,I21*$D$25,0) -> 480679.07 | J30: =IF(6<=Assumptions!$D$54,J21*$D$25,0) -> 485656.18 | K30: =IF(7<=Assumptions!$D$54,K21*$D$25,0) -> 490637.02 | L30: =IF(8<=Assumptions!$D$54,L21*$D$25,0) -> 495619.26 | M30: =IF(9<=Assumptions!$D$54,M21*$D$25,0) -> 500600.46 | N30: =IF(10<=Assumptions!$D$54,N21*$D$25,0) -> 505578.07 | O30: =IF(11<=Assumptions!$D$54,O21*$D$25,0) -> 510549.39 | P30: =IF(12<=Assumptions!$D$54,P21*$D$25,0) -> 515511.61 | Q30: =IF(13<=Assumptions!$D$54,Q21*$D$25,0) -> 520461.77 | R30: =IF(14<=Assumptions!$D$54,R21*$D$25,0) -> 525396.79 | S30: =IF(15<=Assumptions!$D$54,S21*$D$25,0) -> 0 | T30: =IF(16<=Assumptions!$D$54,T21*$D$25,0) -> 0 | U30: =IF(17<=Assumptions!$D$54,U21*$D$25,0) -> 0 | V30: =IF(18<=Assumptions!$D$54,V21*$D$25,0) -> 0 | W30: =IF(19<=Assumptions!$D$54,W21*$D$25,0) -> 0 | X30: =IF(20<=Assumptions!$D$54,X21*$D$25,0) -> 0
B31: Principal repayment | C31: USD | E31: =MIN(E28,E30-E29) -> 111266.65 | F31: =MIN(F28,F30-F29) -> 126778.15 | G31: =MIN(G28,G30-G29) -> 143775.17 | H31: =MIN(H28,H30-H29) -> 162396.95 | I31: =MIN(I28,I30-I29) -> 182795.83 | J31: =MIN(J28,J30-J29) -> 205138.55 | K31: =MIN(K28,K30-K29) -> 229607.54 | L31: =MIN(L28,L30-L29) -> 256402.5 | ... X31: =MIN(X28,X30-X29) -> 0
B32: Closing balance | C32: USD | E32: =E28-E31 -> 3568563.3 | F32: =F28-F31 -> 3441785.2 | G32: =G28-G31 -> 3298010 | H32: =H28-H31 -> 3135613.1 | I32: =I28-I31 -> 2952817.2 | J32: =J28-J31 -> 2747678.7 | K32: =K28-K31 -> 2518071.2 | L32: =L28-L31 -> 2261668.7 | ... X32: =X28-X31 -> 0
B34: DEBT SERVICE RESERVE ACCOUNT
B35: DSRA balance | C35: USD | E35: =IF(E32>0,F30*Assumptions!$D$57/12,0) -> 232895.83 | F35: =IF(F32>0,G30*Assumptions!$D$57/12,0) -> 235372.38 | G35: =IF(G32>0,H30*Assumptions!$D$57/12,0) -> 237853.95 | H35: =IF(H32>0,I30*Assumptions!$D$57/12,0) -> 240339.54 | I35: =IF(I32>0,J30*Assumptions!$D$57/12,0) -> 242828.09 | J35: =IF(J32>0,K30*Assumptions!$D$57/12,0) -> 245318.51 | K35: =IF(K32>0,L30*Assumptions!$D$57/12,0) -> 247809.63 | L35: =IF(L32>0,M30*Assumptions!$D$57/12,0) -> 250300.23 | ... W35: =IF(W32>0,X30*Assumptions!$D$57/12,0) -> 0 | X35: 0
B36: Movement in DSRA | C36: USD | E36: =E35-$D$10 -> 2470.5808 | F36: =F35-E35 -> 2476.5491 | G36: =G35-F35 -> 2481.5678 | H36: =H35-G35 -> 2485.5872 | I36: =I35-H35 -> 2488.5552 | J36: =J35-I35 -> 2490.4179 | K36: =K35-J35 -> 2491.1193 | L36: =L35-K35 -> 2490.601 | M36: =M35-L35 -> 2488.8025 | ... X36: =X35-W35 -> 0

Sheet Financials
B2: CircularEnergies
B3: FINANCIAL STATEMENTS
B4: Income statement, cash flow statement and balance sheet
B6: Period | D6: Construction | E6: Yr 1 | F6: Yr 2 | G6: Yr 3 | H6: Yr 4 | I6: Yr 5 | J6: Yr 6 | K6: Yr 7 | L6: Yr 8 | M6: Yr 9 | N6: Yr 10 | O6: Yr 11 | P6: Yr 12 | Q6: Yr 13 | R6: Yr 14 | S6: Yr 15 | T6: Yr 16 | U6: Yr 17 | V6: Yr 18 | W6: Yr 19 | X6: Yr 20
B8: INCOME STATEMENT
B9: Revenue | C9: USD | E9: =Model!E15 -> 1193766.9 | F9: =Model!F15 -> 1210945.2 | G9: =Model!G15 -> 1228370.7 | H9: =Model!H15 -> 1246046.9 | I9: =Model!I15 -> 1263977.6 | J9: =Model!J15 -> 1282166.2 | K9: =Model!K15 -> 1300616.6 | L9: =Model!L15 -> 1319332.4 | ... X9: =Model!X15 -> 1615967.8
B10: Operating costs | C10: USD | E10: =Model!E18 -> -180365.25 | F10: =Model!F18 -> -186678.03 | G10: =Model!G18 -> -193211.76 | H10: =Model!H18 -> -199974.18 | I10: =Model!I18 -> -206973.27 | J10: =Model!J18 -> -214217.34 | K10: =Model!K18 -> -221714.94 | L10: =Model!L18 -> -229474.97 | ... X10: =Model!X18 -> -346752.43
B11: EBITDA | C11: USD | E11: =E9+E10 -> 1013401.6 | F11: =F9+F10 -> 1024267.1 | G11: =G9+G10 -> 1035158.9 | H11: =H9+H10 -> 1046072.8 | I11: =I9+I10 -> 1057004.3 | J11: =J9+J10 -> 1067948.9 | K11: =K9+K10 -> 1078901.6 | L11: =L9+L10 -> 1089857.5 | ... X11: =X9+X10 -> 1269215.4
B12: Depreciation | C12: USD | E12: =-(Assumptions!$D$30+Debt!$D$8+Debt!$D$9)/Assumptions!$D$67 -> -290274.47 | F12: =-(Assumptions!$D$30+Debt!$D$8+Debt!$D$9)/Assumptions!$D$67 -> -290274.47 | G12: =-(Assumptions!$D$30+Debt!$D$8+Debt!$D$9)/Assumptions!$D$67 -> -290274.47 | H12: =-(Assumptions!$D$30+Debt!$D$8+Debt!$D$9)/Assumptions!$D$67 -> -290274.47 | I12: =-(Assumptions!$D$30+Debt!$D$8+Debt!$D$9)/Assumptions!$D$67 -> -290274.47 | J12: =-(Assumptions!$D$30+Debt!$D$8+Debt!$D$9)/Assumptions!$D$67 -> -290274.47 | K12: =-(Assumptions!$D$30+Debt!$D$8+Debt!$D$9)/Assumptions!$D$67 -> -290274.47 | L12: =-(Assumptions!$D$30+Debt!$D$8+Debt!$D$9)/Assumptions!$D$67 -> -290274.47 | ... X12: =-(Assumptions!$D$30+Debt!$D$8+Debt!$D$9)/Assumptions!$D$67 -> -290274.47
B13: EBIT | C13: USD | E13: =E11+E12 -> 723127.16 | F13: =F11+F12 -> 733992.68 | G13: =G11+G12 -> 744884.45 | H13: =H11+H12 -> 755798.29 | I13: =I11+I12 -> 766729.81 | J13: =J11+J12 -> 777674.38 | K13: =K11+K12 -> 788627.15 | L13: =L11+L12 -> 799583 | ... X13: =X11+X12 -> 978940.89
B14: Interest expense | C14: USD | E14: =-Debt!E29 -> -349583.85 | F14: =-Debt!F29 -> -339013.52 | G14: =-Debt!G29 -> -326969.59 | H14: =-Debt!H29 -> -313310.95 | I14: =-Debt!I29 -> -297883.24 | J14: =-Debt!J29 -> -280517.64 | K14: =-Debt!K29 -> -261029.48 | L14: =-Debt!L29 -> -239216.76 | ... X14: =-Debt!X29 -> 0
B15: Profit before tax | C15: USD | E15: =E13+E14 -> 373543.31 | F15: =F13+F14 -> 394979.16 | G15: =G13+G14 -> 417914.85 | H15: =H13+H14 -> 442487.34 | I15: =I13+I14 -> 468846.57 | J15: =J13+J14 -> 497156.74 | K15: =K13+K14 -> 527597.67 | L15: =L13+L14 -> 560366.24 | ... X15: =X13+X14 -> 978940.89
B16: Taxation | C16: USD | E16: =Model!E29 -> 0 | F16: =Model!F29 -> 0 | G16: =Model!G29 -> 0 | H16: =Model!H29 -> 0 | I16: =Model!I29 -> 0 | J16: =Model!J29 -> -259852.3 | K16: =Model!K29 -> -269897.81 | L16: =Model!L29 -> -280711.43 | ... X16: =Model!X29 -> -418841.07
B17: Net income | C17: USD | E17: =E15+E16 -> 373543.31 | F17: =F15+F16 -> 394979.16 | G17: =G15+G16 -> 417914.85 | H17: =H15+H16 -> 442487.34 | I17: =I15+I16 -> 468846.57 | J17: =J15+J16 -> 237304.44 | K17: =K15+K16 -> 257699.86 | L17: =L15+L16 -> 279654.8 | ... X17: =X15+X16 -> 560099.82
B19: CASH FLOW STATEMENT
B20: EBITDA | C20: USD | E20: =Model!E19 -> 1013401.6 | F20: =Model!F19 -> 1024267.1 | G20: =Model!G19 -> 1035158.9 | H20: =Model!H19 -> 1046072.8 | I20: =Model!I19 -> 1057004.3 | J20: =Model!J19 -> 1067948.9 | K20: =Model!K19 -> 1078901.6 | L20: =Model!L19 -> 1089857.5 | ... X20: =Model!X19 -> 1269215.4
B21: Taxation paid | C21: USD | E21: =Model!E29 -> 0 | F21: =Model!F29 -> 0 | G21: =Model!G29 -> 0 | H21: =Model!H29 -> 0 | I21: =Model!I29 -> 0 | J21: =Model!J29 -> -259852.3 | K21: =Model!K29 -> -269897.81 | L21: =Model!L29 -> -280711.43 | ... X21: =Model!X29 -> -418841.07
B22: Debt service | C22: USD | E22: =-Debt!E30 -> -460850.5 | F22: =-Debt!F30 -> -465791.67 | G22: =-Debt!G30 -> -470744.76 | H22: =-Debt!H30 -> -475707.9 | I22: =-Debt!I30 -> -480679.07 | J22: =-Debt!J30 -> -485656.18 | K22: =-Debt!K30 -> -490637.02 | L22: =-Debt!L30 -> -495619.26 | ... X22: =-Debt!X30 -> 0
B23: Movement in DSRA | C23: USD | E23: =-Debt!E36 -> -2470.5808 | F23: =-Debt!F36 -> -2476.5491 | G23: =-Debt!G36 -> -2481.5678 | H23: =-Debt!H36 -> -2485.5872 | I23: =-Debt!I36 -> -2488.5552 | J23: =-Debt!J36 -> -2490.4179 | K23: =-Debt!K36 -> -2491.1193 | L23: =-Debt!L36 -> -2490.601 | ... X23: =-Debt!X36 -> 0
B24: Free cash flow to equity | C24: USD | D24: =-Debt!$D$15 -> -2406084.6 | E24: =SUM(E20:E23) -> 550080.54 | F24: =SUM(F20:F23) -> 555998.93 | G24: =SUM(G20:G23) -> 561932.58 | H24: =SUM(H20:H23) -> 567879.27 | I24: =SUM(I20:I23) -> 573836.65 | J24: =SUM(J20:J23) -> 319949.95 | K24: =SUM(K20:K23) -> 315875.67 | L24: =SUM(L20:L23) -> 311036.17 | ... X24: =SUM(X20:X23) -> 850374.29
B26: BALANCE SHEET
B27: Net fixed assets | C27: USD | E27: =(Assumptions!$D$30+Debt!$D$8+Debt!$D$9)-(Assumptions!$D$30+Debt!$D$8+Debt!$D$9)/Assumptions!$D$67*1 -> 5515214.9 | F27: =(Assumptions!$D$30+Debt!$D$8+Debt!$D$9)-(Assumptions!$D$30+Debt!$D$8+Debt!$D$9)/Assumptions!$D$67*2 -> 5224940.4 | G27: =(Assumptions!$D$30+Debt!$D$8+Debt!$D$9)-(Assumptions!$D$30+Debt!$D$8+Debt!$D$9)/Assumptions!$D$67*3 -> 4934666 | H27: =(Assumptions!$D$30+Debt!$D$8+Debt!$D$9)-(Assumptions!$D$30+Debt!$D$8+Debt!$D$9)/Assumptions!$D$67*4 -> 4644391.5 | I27: =(Assumptions!$D$30+Debt!$D$8+Debt!$D$9)-(Assumptions!$D$30+Debt!$D$8+Debt!$D$9)/Assumptions!$D$67*5 -> 4354117 | J27: =(Assumptions!$D$30+Debt!$D$8+Debt!$D$9)-(Assumptions!$D$30+Debt!$D$8+Debt!$D$9)/Assumptions!$D$67*6 -> 4063842.6 | K27: =(Assumptions!$D$30+Debt!$D$8+Debt!$D$9)-(Assumptions!$D$30+Debt!$D$8+Debt!$D$9)/Assumptions!$D$67*7 -> 3773568.1 | L27: =(Assumptions!$D$30+Debt!$D$8+Debt!$D$9)-(Assumptions!$D$30+Debt!$D$8+Debt!$D$9)/Assumptions!$D$67*8 -> 3483293.6 | M27: =(Assumptions!$D$30+Debt!$D$8+Debt!$D$9)-(Assumptions!$D$30+Debt!$D$8+Debt!$D$9)/Assumptions!$D$67*9 -> 3193019.2 | N27: =(Assumptions!$D$30+Debt!$D$8+Debt!$D$9)-(Assumptions!$D$30+Debt!$D$8+Debt!$D$9)/Assumptions!$D$67*10 -> 2902744.7 | O27: =(Assumptions!$D$30+Debt!$D$8+Debt!$D$9)-(Assumptions!$D$30+Debt!$D$8+Debt!$D$9)/Assumptions!$D$67*11 -> 2612470.2 | P27: =(Assumptions!$D$30+Debt!$D$8+Debt!$D$9)-(Assumptions!$D$30+Debt!$D$8+Debt!$D$9)/Assumptions!$D$67*12 -> 2322195.8 | Q27: =(Assumptions!$D$30+Debt!$D$8+Debt!$D$9)-(Assumptions!$D$30+Debt!$D$8+Debt!$D$9)/Assumptions!$D$67*13 -> 2031921.3 | R27: =(Assumptions!$D$30+Debt!$D$8+Debt!$D$9)-(Assumptions!$D$30+Debt!$D$8+Debt!$D$9)/Assumptions!$D$67*14 -> 1741646.8 | S27: =(Assumptions!$D$30+Debt!$D$8+Debt!$D$9)-(Assumptions!$D$30+Debt!$D$8+Debt!$D$9)/Assumptions!$D$67*15 -> 1451372.3 | T27: =(Assumptions!$D$30+Debt!$D$8+Debt!$D$9)-(Assumptions!$D$30+Debt!$D$8+Debt!$D$9)/Assumptions!$D$67*16 -> 1161097.9 | U27: =(Assumptions!$D$30+Debt!$D$8+Debt!$D$9)-(Assumptions!$D$30+Debt!$D$8+Debt!$D$9)/Assumptions!$D$67*17 -> 870823.41 | V27: =(Assumptions!$D$30+Debt!$D$8+Debt!$D$9)-(Assumptions!$D$30+Debt!$D$8+Debt!$D$9)/Assumptions!$D$67*18 -> 580548.94 | W27: =(Assumptions!$D$30+Debt!$D$8+Debt!$D$9)-(Assumptions!$D$30+Debt!$D$8+Debt!$D$9)/Assumptions!$D$67*19 -> 290274.47 | X27: =(Assumptions!$D$30+Debt!$D$8+Debt!$D$9)-(Assumptions!$D$30+Debt!$D$8+Debt!$D$9)/Assumptions!$D$67*20 -> 0
B28: Debt service reserve | C28: USD | E28: =Debt!E35 -> 232895.83 | F28: =Debt!F35 -> 235372.38 | G28: =Debt!G35 -> 237853.95 | H28: =Debt!H35 -> 240339.54 | I28: =Debt!I35 -> 242828.09 | J28: =Debt!J35 -> 245318.51 | K28: =Debt!K35 -> 247809.63 | L28: =Debt!L35 -> 250300.23 | ... X28: =Debt!X35 -> 0
B29: Cash | C29: USD | E29: =Assumptions!$D$59 -> 50000 | F29: =Assumptions!$D$59 -> 50000 | G29: =Assumptions!$D$59 -> 50000 | H29: =Assumptions!$D$59 -> 50000 | I29: =Assumptions!$D$59 -> 50000 | J29: =Assumptions!$D$59 -> 50000 | K29: =Assumptions!$D$59 -> 50000 | L29: =Assumptions!$D$59 -> 50000 | ... X29: =Assumptions!$D$59 -> 50000
B30: Total assets | C30: USD | E30: =SUM(E27:E29) -> 5798110.7 | F30: =SUM(F27:F29) -> 5510312.8 | G30: =SUM(G27:G29) -> 5222519.9 | H30: =SUM(H27:H29) -> 4934731 | I30: =SUM(I27:I29) -> 4646945.1 | J30: =SUM(J27:J29) -> 4359161.1 | K30: =SUM(K27:K29) -> 4071377.7 | L30: =SUM(L27:L29) -> 3783593.9 | ... X30: =SUM(X27:X29) -> 50000
B32: Senior debt | C32: USD | E32: =Debt!E32 -> 3568563.3 | F32: =Debt!F32 -> 3441785.2 | G32: =Debt!G32 -> 3298010 | H32: =Debt!H32 -> 3135613.1 | I32: =Debt!I32 -> 2952817.2 | J32: =Debt!J32 -> 2747678.7 | K32: =Debt!K32 -> 2518071.2 | L32: =Debt!L32 -> 2261668.7 | ... X32: =Debt!X32 -> 0
B33: Share capital | C33: USD | E33: =Debt!$D$15 -> 2406084.6 | F33: =Debt!$D$15 -> 2406084.6 | G33: =Debt!$D$15 -> 2406084.6 | H33: =Debt!$D$15 -> 2406084.6 | I33: =Debt!$D$15 -> 2406084.6 | J33: =Debt!$D$15 -> 2406084.6 | K33: =Debt!$D$15 -> 2406084.6 | L33: =Debt!$D$15 -> 2406084.6 | ... X33: =Debt!$D$15 -> 2406084.6
B34: Retained earnings | C34: USD | E34: =E17-E24 -> -176537.23 | F34: =E34+F17-F24 -> -337557.01 | G34: =F34+G17-G24 -> -481574.74 | H34: =G34+H17-H24 -> -606966.67 | I34: =H34+I17-I24 -> -711956.75 | J34: =I34+J17-J24 -> -794602.26 | K34: =J34+K17-K24 -> -852778.07 | L34: =K34+L17-L24 -> -884159.43 | M34: =L34+M17-M24 -> -886203.16 | ... X34: =W34+X17-X24 -> -2356084.6
B35: Total liabilities & equity | C35: USD | E35: =SUM(E32:E34) -> 5798110.7 | F35: =SUM(F32:F34) -> 5510312.8 | G35: =SUM(G32:G34) -> 5222519.9 | H35: =SUM(H32:H34) -> 4934731 | I35: =SUM(I32:I34) -> 4646945.1 | J35: =SUM(J32:J34) -> 4359161.1 | K35: =SUM(K32:K34) -> 4071377.7 | L35: =SUM(L32:L34) -> 3783593.9 | ... X35: =SUM(X32:X34) -> 50000
B36: Balance check | C36: USD | E36: =E30-E35 -> 0 | F36: =F30-F35 -> 0 | G36: =G30-G35 -> 0 | H36: =H30-H35 -> 0 | I36: =I30-I35 -> 0 | J36: =J30-J35 -> 0 | K36: =K30-K35 -> 0 | L36: =L30-L35 -> 0 | ... X36: =X30-X35 -> -9.3132257e-10

Sheet Returns
B2: CircularEnergies
B3: RETURNS & COVERAGE
B4: NPV, IRR, DSCR, LLCR and payback
B6: Period | D6: Construction | E6: Yr 1 | F6: Yr 2 | G6: Yr 3 | H6: Yr 4 | I6: Yr 5 | J6: Yr 6 | K6: Yr 7 | L6: Yr 8 | M6: Yr 9 | N6: Yr 10 | O6: Yr 11 | P6: Yr 12 | Q6: Yr 13 | R6: Yr 14 | S6: Yr 15 | T6: Yr 16 | U6: Yr 17 | V6: Yr 18 | W6: Yr 19 | X6: Yr 20
B8: COVERAGE RATIOS
B9: CFADS | C9: USD | E9: =Model!E32 -> 1013401.6 | F9: =Model!F32 -> 1024267.1 | G9: =Model!G32 -> 1035158.9 | H9: =Model!H32 -> 1046072.8 | I9: =Model!I32 -> 1057004.3 | J9: =Model!J32 -> 808096.55 | K9: =Model!K32 -> 809003.81 | L9: =Model!L32 -> 809146.03 | ... X9: =Model!X32 -> 850374.29
B10: Debt service | C10: USD | E10: =Debt!E30 -> 460850.5 | F10: =Debt!F30 -> 465791.67 | G10: =Debt!G30 -> 470744.76 | H10: =Debt!H30 -> 475707.9 | I10: =Debt!I30 -> 480679.07 | J10: =Debt!J30 -> 485656.18 | K10: =Debt!K30 -> 490637.02 | L10: =Debt!L30 -> 495619.26 | ... X10: =Debt!X30 -> 0
B11: DSCR | C11: x | E11: =IFERROR(IF(E10=0,"",E9/E10),"") -> 2.1989813 | F11: =IFERROR(IF(F10=0,"",F9/F10),"") -> 2.1989813 | G11: =IFERROR(IF(G10=0,"",G9/G10),"") -> 2.1989813 | H11: =IFERROR(IF(H10=0,"",H9/H10),"") -> 2.1989813 | I11: =IFERROR(IF(I10=0,"",I9/I10),"") -> 2.1989813 | J11: =IFERROR(IF(J10=0,"",J9/J10),"") -> 1.6639272 | K11: =IFERROR(IF(K10=0,"",K9/K10),"") -> 1.6488846 | L11: =IFERROR(IF(L10=0,"",L9/L10),"") -> 1.632596 | ... X11: =IFERROR(IF(X10=0,"",X9/X10),"")
B12: LLCR | C12: x | E12: =IFERROR(IF(Debt!E28=0,"",NPV(Assumptions!$D$53,E9:X9)/Debt!E28),"") -> 2.1686715 | F12: =IFERROR(IF(Debt!F28=0,"",NPV(Assumptions!$D$53,F9:X9)/Debt!F28),"") -> 2.1647573 | G12: =IFERROR(IF(Debt!G28=0,"",NPV(Assumptions!$D$53,G9:X9)/Debt!G28),"") -> 2.1601256 | H12: =IFERROR(IF(Debt!H28=0,"",NPV(Assumptions!$D$53,H9:X9)/Debt!H28),"") -> 2.1545795 | I12: =IFERROR(IF(Debt!I28=0,"",NPV(Assumptions!$D$53,I9:X9)/Debt!I28),"") -> 2.1478432 | J12: =IFERROR(IF(Debt!J28=0,"",NPV(Assumptions!$D$53,J9:X9)/Debt!J28),"") -> 2.1395187 | K12: =IFERROR(IF(Debt!K28=0,"",NPV(Assumptions!$D$53,K9:X9)/Debt!K28),"") -> 2.2235801 | L12: =IFERROR(IF(Debt!L28=0,"",NPV(Assumptions!$D$53,L9:X9)/Debt!L28),"") -> 2.3355575 | M12: =IFERROR(IF(Debt!M28=0,"",NPV(Assumptions!$D$53,M9:X9)/Debt!M28),"") -> 2.4896036 | N12: =IFERROR(IF(Debt!N28=0,"",NPV(Assumptions!$D$53,N9:X9)/Debt!N28),"") -> 2.7111958 | O12: =IFERROR(IF(Debt!O28=0,"",NPV(Assumptions!$D$53,O9:X9)/Debt!O28),"") -> 3.051291 | P12: =IFERROR(IF(Debt!P28=0,"",NPV(Assumptions!$D$53,P9:X9)/Debt!P28),"") -> 3.6287906 | Q12: =IFERROR(IF(Debt!Q28=0,"",NPV(Assumptions!$D$53,Q9:X9)/Debt!Q28),"") -> 4.8004003 | R12: =IFERROR(IF(Debt!R28=0,"",NPV(Assumptions!$D$53,R9:X9)/Debt!R28),"") -> 8.3496505 | S12: =IFERROR(IF(Debt!S28=0,"",NPV(Assumptions!$D$53,S9:X9)/Debt!S28),"") | T12: =IFERROR(IF(Debt!T28=0,"",NPV(Assumptions!$D$53,T9:X9)/Debt!T28),"") | U12: =IFERROR(IF(Debt!U28=0,"",NPV(Assumptions!$D$53,U9:X9)/Debt!U28),"") | V12: =IFERROR(IF(Debt!V28=0,"",NPV(Assumptions!$D$53,V9:X9)/Debt!V28),"") | W12: =IFERROR(IF(Debt!W28=0,"",NPV(Assumptions!$D$53,W9:X9)/Debt!W28),"") | X12: =IFERROR(IF(Debt!X28=0,"",NPV(Assumptions!$D$53,X9:X9)/Debt!X28),"")
B14: HEADLINE METRICS
B15: Minimum DSCR | D15: =MIN(E11:X11) -> 1.5019476 | E15: Covenant 1.30x
B16: Average DSCR | D16: =AVERAGE(E11:X11) -> 1.8078006
B17: LLCR at financial close | D17: =E12 -> 2.1686715
B19: Project IRR (pre-financing) | D19: =IRR(D30:X30) -> 0.15184688 | E19: Post-tax, pre-financing
B20: Equity IRR | D20: =IRR(Financials!D24:X24) -> 0.19909563 | E20: Post-tax, post-debt
B21: Equity NPV at hurdle rate | D21: =Financials!D24+NPV(Assumptions!$D$71,Financials!E24:X24) -> 220586.42
B23: Total project cost | D23: =Debt!$D$12 -> 6085914.6
B24: Senior debt | D24: =Debt!$D$14 -> 3679830
B25: Sponsor equity | D25: =Debt!$D$15 -> 2406084.6
B26: Capital cost per Wp | D26: =Debt!$D$7/(Assumptions!$D$14*1000000) -> 1.1151 | E26: Installed, incl. storage
B29: PROJECT CASH FLOW (PRE-FINANCING)
B30: Project free cash flow | C30: USD | D30: =-Debt!$D$7-Debt!$D$8 -> -5750291.9 | E30: =Model!E19+Model!E29 -> 1013401.6 | F30: =Model!F19+Model!F29 -> 1024267.1 | G30: =Model!G19+Model!G29 -> 1035158.9 | H30: =Model!H19+Model!H29 -> 1046072.8 | I30: =Model!I19+Model!I29 -> 1057004.3 | J30: =Model!J19+Model!J29 -> 808096.55 | K30: =Model!K19+Model!K29 -> 809003.81 | L30: =Model!L19+Model!L29 -> 809146.03 | ... X30: =Model!X19+Model!X29 -> 850374.29

Sheet Sensitivities
B2: CircularEnergies
B3: SENSITIVITY ANALYSIS
B4: Downside cases against the debt service profile fixed at financial close
B6: Period | D6: Construction | E6: Yr 1 | F6: Yr 2 | G6: Yr 3 | H6: Yr 4 | I6: Yr 5 | J6: Yr 6 | K6: Yr 7 | L6: Yr 8 | M6: Yr 9 | N6: Yr 10 | O6: Yr 11 | P6: Yr 12 | Q6: Yr 13 | R6: Yr 14 | S6: Yr 15 | T6: Yr 16 | U6: Yr 17 | V6: Yr 18 | W6: Yr 19 | X6: Yr 20
B8: BASE CASE
B9: Revenue | C9: USD | E9: =MAX(MIN(Model!E10*1,Assumptions!$D$35),Assumptions!$D$35*Assumptions!$D$36)*Model!E14*1 -> 1193766.9 | F9: =MAX(MIN(Model!F10*1,Assumptions!$D$35),Assumptions!$D$35*Assumptions!$D$36)*Model!F14*1 -> 1210945.2 | G9: =MAX(MIN(Model!G10*1,Assumptions!$D$35),Assumptions!$D$35*Assumptions!$D$36)*Model!G14*1 -> 1228370.7 | H9: =MAX(MIN(Model!H10*1,Assumptions!$D$35),Assumptions!$D$35*Assumptions!$D$36)*Model!H14*1 -> 1246046.9 | I9: =MAX(MIN(Model!I10*1,Assumptions!$D$35),Assumptions!$D$35*Assumptions!$D$36)*Model!I14*1 -> 1263977.6 | J9: =MAX(MIN(Model!J10*1,Assumptions!$D$35),Assumptions!$D$35*Assumptions!$D$36)*Model!J14*1 -> 1282166.2 | K9: =MAX(MIN(Model!K10*1,Assumptions!$D$35),Assumptions!$D$35*Assumptions!$D$36)*Model!K14*1 -> 1300616.6 | L9: =MAX(MIN(Model!L10*1,Assumptions!$D$35),Assumptions!$D$35*Assumptions!$D$36)*Model!L14*1 -> 1319332.4 | ... X9: =MAX(MIN(Model!X10*1,Assumptions!$D$35),Assumptions!$D$35*Assumptions!$D$36)*Model!X14*1 -> 1615967.8
B10: Operating costs | C10: USD | E10: =Model!E18*1 -> -180365.25 | F10: =Model!F18*1 -> -186678.03 | G10: =Model!G18*1 -> -193211.76 | H10: =Model!H18*1 -> -199974.18 | I10: =Model!I18*1 -> -206973.27 | J10: =Model!J18*1 -> -214217.34 | K10: =Model!K18*1 -> -221714.94 | L10: =Model!L18*1 -> -229474.97 | ... X10: =Model!X18*1 -> -346752.43
B11: EBITDA | C11: USD | E11: =E9+E10 -> 1013401.6 | F11: =F9+F10 -> 1024267.1 | G11: =G9+G10 -> 1035158.9 | H11: =H9+H10 -> 1046072.8 | I11: =I9+I10 -> 1057004.3 | J11: =J9+J10 -> 1067948.9 | K11: =K9+K10 -> 1078901.6 | L11: =L9+L10 -> 1089857.5 | ... X11: =X9+X10 -> 1269215.4
B12: Taxation | C12: USD | E12: =IF(Model!E27=1,0,-MAX(0,E11-Debt!E29-Model!E25)*(Assumptions!$D$62+Assumptions!$D$63)) -> 0 | F12: =IF(Model!F27=1,0,-MAX(0,F11-Debt!F29-Model!F25)*(Assumptions!$D$62+Assumptions!$D$63)) -> 0 | G12: =IF(Model!G27=1,0,-MAX(0,G11-Debt!G29-Model!G25)*(Assumptions!$D$62+Assumptions!$D$63)) -> 0 | H12: =IF(Model!H27=1,0,-MAX(0,H11-Debt!H29-Model!H25)*(Assumptions!$D$62+Assumptions!$D$63)) -> 0 | I12: =IF(Model!I27=1,0,-MAX(0,I11-Debt!I29-Model!I25)*(Assumptions!$D$62+Assumptions!$D$63)) -> 0 | J12: =IF(Model!J27=1,0,-MAX(0,J11-Debt!J29-Model!J25)*(Assumptions!$D$62+Assumptions!$D$63)) -> -259852.3 | K12: =IF(Model!K27=1,0,-MAX(0,K11-Debt!K29-Model!K25)*(Assumptions!$D$62+Assumptions!$D$63)) -> -269897.81 | L12: =IF(Model!L27=1,0,-MAX(0,L11-Debt!L29-Model!L25)*(Assumptions!$D$62+Assumptions!$D$63)) -> -280711.43 | ... X12: =IF(Model!X27=1,0,-MAX(0,X11-Debt!X29-Model!X25)*(Assumptions!$D$62+Assumptions!$D$63)) -> -418841.07
B13: CFADS | C13: USD | E13: =E11+E12 -> 1013401.6 | F13: =F11+F12 -> 1024267.1 | G13: =G11+G12 -> 1035158.9 | H13: =H11+H12 -> 1046072.8 | I13: =I11+I12 -> 1057004.3 | J13: =J11+J12 -> 808096.55 | K13: =K11+K12 -> 809003.81 | L13: =L11+L12 -> 809146.03 | ... X13: =X11+X12 -> 850374.29
B14: Debt service | C14: USD | E14: =Debt!E30 -> 460850.5 | F14: =Debt!F30 -> 465791.67 | G14: =Debt!G30 -> 470744.76 | H14: =Debt!H30 -> 475707.9 | I14: =Debt!I30 -> 480679.07 | J14: =Debt!J30 -> 485656.18 | K14: =Debt!K30 -> 490637.02 | L14: =Debt!L30 -> 495619.26 | ... X14: =Debt!X30 -> 0
B15: DSCR | C15: x | E15: =IFERROR(IF(E14=0,"",E13/E14),"") -> 2.1989813 | F15: =IFERROR(IF(F14=0,"",F13/F14),"") -> 2.1989813 | G15: =IFERROR(IF(G14=0,"",G13/G14),"") -> 2.1989813 | H15: =IFERROR(IF(H14=0,"",H13/H14),"") -> 2.1989813 | I15: =IFERROR(IF(I14=0,"",I13/I14),"") -> 2.1989813 | J15: =IFERROR(IF(J14=0,"",J13/J14),"") -> 1.6639272 | K15: =IFERROR(IF(K14=0,"",K13/K14),"") -> 1.6488846 | L15: =IFERROR(IF(L14=0,"",L13/L14),"") -> 1.632596 | ... X15: =IFERROR(IF(X14=0,"",X13/X14),"")
B16: Free cash flow to equity | C16: USD | D16: =-Debt!$D$15 -> -2406084.6 | E16: =E13-E14-Debt!E36 -> 550080.54 | F16: =F13-F14-Debt!F36 -> 555998.93 | G16: =G13-G14-Debt!G36 -> 561932.58 | H16: =H13-H14-Debt!H36 -> 567879.27 | I16: =I13-I14-Debt!I36 -> 573836.65 | J16: =J13-J14-Debt!J36 -> 319949.95 | K16: =K13-K14-Debt!K36 -> 315875.67 | L16: =L13-L14-Debt!L36 -> 311036.17 | ... X16: =X13-X14-Debt!X36 -> 850374.29
B18: TARIFF -10%
B19: Revenue | C19: USD | E19: =MAX(MIN(Model!E10*1,Assumptions!$D$35),Assumptions!$D$35*Assumptions!$D$36)*Model!E14*0.9 -> 1074390.2 | F19: =MAX(MIN(Model!F10*1,Assumptions!$D$35),Assumptions!$D$35*Assumptions!$D$36)*Model!F14*0.9 -> 1089850.7 | G19: =MAX(MIN(Model!G10*1,Assumptions!$D$35),Assumptions!$D$35*Assumptions!$D$36)*Model!G14*0.9 -> 1105533.6 | H19: =MAX(MIN(Model!H10*1,Assumptions!$D$35),Assumptions!$D$35*Assumptions!$D$36)*Model!H14*0.9 -> 1121442.2 | I19: =MAX(MIN(Model!I10*1,Assumptions!$D$35),Assumptions!$D$35*Assumptions!$D$36)*Model!I14*0.9 -> 1137579.8 | J19: =MAX(MIN(Model!J10*1,Assumptions!$D$35),Assumptions!$D$35*Assumptions!$D$36)*Model!J14*0.9 -> 1153949.6 | K19: =MAX(MIN(Model!K10*1,Assumptions!$D$35),Assumptions!$D$35*Assumptions!$D$36)*Model!K14*0.9 -> 1170554.9 | L19: =MAX(MIN(Model!L10*1,Assumptions!$D$35),Assumptions!$D$35*Assumptions!$D$36)*Model!L14*0.9 -> 1187399.2 | ... X19: =MAX(MIN(Model!X10*1,Assumptions!$D$35),Assumptions!$D$35*Assumptions!$D$36)*Model!X14*0.9 -> 1454371
B20: Operating costs | C20: USD | E20: =Model!E18*1 -> -180365.25 | F20: =Model!F18*1 -> -186678.03 | G20: =Model!G18*1 -> -193211.76 | H20: =Model!H18*1 -> -199974.18 | I20: =Model!I18*1 -> -206973.27 | J20: =Model!J18*1 -> -214217.34 | K20: =Model!K18*1 -> -221714.94 | L20: =Model!L18*1 -> -229474.97 | ... X20: =Model!X18*1 -> -346752.43
B21: EBITDA | C21: USD | E21: =E19+E20 -> 894024.94 | F21: =F19+F20 -> 903172.63 | G21: =G19+G20 -> 912321.85 | H21: =H19+H20 -> 921468.07 | I21: =I19+I20 -> 930606.52 | J21: =J19+J20 -> 939732.23 | K21: =K19+K20 -> 948839.96 | L21: =L19+L20 -> 957924.22 | ... X21: =X19+X20 -> 1107618.6
B22: Taxation | C22: USD | E22: =IF(Model!E27=1,0,-MAX(0,E21-Debt!E29-Model!E25)*(Assumptions!$D$62+Assumptions!$D$63)) -> 0 | F22: =IF(Model!F27=1,0,-MAX(0,F21-Debt!F29-Model!F25)*(Assumptions!$D$62+Assumptions!$D$63)) -> 0 | G22: =IF(Model!G27=1,0,-MAX(0,G21-Debt!G29-Model!G25)*(Assumptions!$D$62+Assumptions!$D$63)) -> 0 | H22: =IF(Model!H27=1,0,-MAX(0,H21-Debt!H29-Model!H25)*(Assumptions!$D$62+Assumptions!$D$63)) -> 0 | I22: =IF(Model!I27=1,0,-MAX(0,I21-Debt!I29-Model!I25)*(Assumptions!$D$62+Assumptions!$D$63)) -> 0 | J22: =IF(Model!J27=1,0,-MAX(0,J21-Debt!J29-Model!J25)*(Assumptions!$D$62+Assumptions!$D$63)) -> -217540.82 | K22: =IF(Model!K27=1,0,-MAX(0,K21-Debt!K29-Model!K25)*(Assumptions!$D$62+Assumptions!$D$63)) -> -226977.46 | L22: =IF(Model!L27=1,0,-MAX(0,L21-Debt!L29-Model!L25)*(Assumptions!$D$62+Assumptions!$D$63)) -> -237173.46 | ... X22: =IF(Model!X27=1,0,-MAX(0,X21-Debt!X29-Model!X25)*(Assumptions!$D$62+Assumptions!$D$63)) -> -365514.13
B23: CFADS | C23: USD | E23: =E21+E22 -> 894024.94 | F23: =F21+F22 -> 903172.63 | G23: =G21+G22 -> 912321.85 | H23: =H21+H22 -> 921468.07 | I23: =I21+I22 -> 930606.52 | J23: =J21+J22 -> 722191.42 | K23: =K21+K22 -> 721862.5 | L23: =L21+L22 -> 720750.76 | ... X23: =X21+X22 -> 742104.45
B24: Debt service | C24: USD | E24: =Debt!E30 -> 460850.5 | F24: =Debt!F30 -> 465791.67 | G24: =Debt!G30 -> 470744.76 | H24: =Debt!H30 -> 475707.9 | I24: =Debt!I30 -> 480679.07 | J24: =Debt!J30 -> 485656.18 | K24: =Debt!K30 -> 490637.02 | L24: =Debt!L30 -> 495619.26 | ... X24: =Debt!X30 -> 0
B25: DSCR | C25: x | E25: =IFERROR(IF(E24=0,"",E23/E24),"") -> 1.9399457 | F25: =IFERROR(IF(F24=0,"",F23/F24),"") -> 1.9390056 | G25: =IFERROR(IF(G24=0,"",G23/G24),"") -> 1.9380393 | H25: =IFERROR(IF(H24=0,"",H23/H24),"") -> 1.937046 | I25: =IFERROR(IF(I24=0,"",I23/I24),"") -> 1.9360246 | J25: =IFERROR(IF(J24=0,"",J23/J24),"") -> 1.4870426 | K25: =IFERROR(IF(K24=0,"",K23/K24),"") -> 1.4712761 | L25: =IFERROR(IF(L24=0,"",L23/L24),"") -> 1.4542428 | ... X25: =IFERROR(IF(X24=0,"",X23/X24),"")
B26: Free cash flow to equity | C26: USD | D26: =-Debt!$D$15 -> -2406084.6 | E26: =E23-E24-Debt!E36 -> 430703.85 | F26: =F23-F24-Debt!F36 -> 434904.41 | G26: =G23-G24-Debt!G36 -> 439095.52 | H26: =H23-H24-Debt!H36 -> 443274.58 | I26: =I23-I24-Debt!I36 -> 447438.89 | J26: =J23-J24-Debt!J36 -> 234044.81 | K26: =K23-K24-Debt!K36 -> 228734.36 | L26: =L23-L24-Debt!L36 -> 222640.9 | ... X26: =X23-X24-Debt!X36 -> 742104.45
B28: GENERATION P90 (-7%)
B29: Revenue | C29: USD | E29: =MAX(MIN(Model!E10*0.93,Assumptions!$D$35),Assumptions!$D$35*Assumptions!$D$36)*Model!E14*1 -> 1110203.2 | F29: =MAX(MIN(Model!F10*0.93,Assumptions!$D$35),Assumptions!$D$35*Assumptions!$D$36)*Model!F14*1 -> 1131435 | G29: =MAX(MIN(Model!G10*0.93,Assumptions!$D$35),Assumptions!$D$35*Assumptions!$D$36)*Model!G14*1 -> 1154063.7 | H29: =MAX(MIN(Model!H10*0.93,Assumptions!$D$35),Assumptions!$D$35*Assumptions!$D$36)*Model!H14*1 -> 1177145 | I29: =MAX(MIN(Model!I10*0.93,Assumptions!$D$35),Assumptions!$D$35*Assumptions!$D$36)*Model!I14*1 -> 1200687.9 | J29: =MAX(MIN(Model!J10*0.93,Assumptions!$D$35),Assumptions!$D$35*Assumptions!$D$36)*Model!J14*1 -> 1224701.6 | K29: =MAX(MIN(Model!K10*0.93,Assumptions!$D$35),Assumptions!$D$35*Assumptions!$D$36)*Model!K14*1 -> 1249195.7 | L29: =MAX(MIN(Model!L10*0.93,Assumptions!$D$35),Assumptions!$D$35*Assumptions!$D$36)*Model!L14*1 -> 1274179.6 | ... X29: =MAX(MIN(Model!X10*0.93,Assumptions!$D$35),Assumptions!$D$35*Assumptions!$D$36)*Model!X14*1 -> 1615967.8
B30: Operating costs | C30: USD | E30: =Model!E18*1 -> -180365.25 | F30: =Model!F18*1 -> -186678.03 | G30: =Model!G18*1 -> -193211.76 | H30: =Model!H18*1 -> -199974.18 | I30: =Model!I18*1 -> -206973.27 | J30: =Model!J18*1 -> -214217.34 | K30: =Model!K18*1 -> -221714.94 | L30: =Model!L18*1 -> -229474.97 | ... X30: =Model!X18*1 -> -346752.43
B31: EBITDA | C31: USD | E31: =E29+E30 -> 929837.94 | F31: =F29+F30 -> 944756.97 | G31: =G29+G30 -> 960851.94 | H31: =H29+H30 -> 977170.8 | I31: =I29+I30 -> 993714.6 | J31: =J29+J30 -> 1010484.3 | K31: =K29+K30 -> 1027480.7 | L31: =L29+L30 -> 1044704.6 | ... X31: =X29+X30 -> 1269215.4
B32: Taxation | C32: USD | E32: =IF(Model!E27=1,0,-MAX(0,E31-Debt!E29-Model!E25)*(Assumptions!$D$62+Assumptions!$D$63)) -> 0 | F32: =IF(Model!F27=1,0,-MAX(0,F31-Debt!F29-Model!F25)*(Assumptions!$D$62+Assumptions!$D$63)) -> 0 | G32: =IF(Model!G27=1,0,-MAX(0,G31-Debt!G29-Model!G25)*(Assumptions!$D$62+Assumptions!$D$63)) -> 0 | H32: =IF(Model!H27=1,0,-MAX(0,H31-Debt!H29-Model!H25)*(Assumptions!$D$62+Assumptions!$D$63)) -> 0 | I32: =IF(Model!I27=1,0,-MAX(0,I31-Debt!I29-Model!I25)*(Assumptions!$D$62+Assumptions!$D$63)) -> 0 | J32: =IF(Model!J27=1,0,-MAX(0,J31-Debt!J29-Model!J25)*(Assumptions!$D$62+Assumptions!$D$63)) -> -240889 | K32: =IF(Model!K27=1,0,-MAX(0,K31-Debt!K29-Model!K25)*(Assumptions!$D$62+Assumptions!$D$63)) -> -252928.91 | L32: =IF(Model!L27=1,0,-MAX(0,L31-Debt!L29-Model!L25)*(Assumptions!$D$62+Assumptions!$D$63)) -> -265810.99 | ... X32: =IF(Model!X27=1,0,-MAX(0,X31-Debt!X29-Model!X25)*(Assumptions!$D$62+Assumptions!$D$63)) -> -418841.07
B33: CFADS | C33: USD | E33: =E31+E32 -> 929837.94 | F33: =F31+F32 -> 944756.97 | G33: =G31+G32 -> 960851.94 | H33: =H31+H32 -> 977170.8 | I33: =I31+I32 -> 993714.6 | J33: =J31+J32 -> 769595.3 | K33: =K31+K32 -> 774551.81 | L33: =L31+L32 -> 778893.62 | ... X33: =X31+X32 -> 850374.29
B34: Debt service | C34: USD | E34: =Debt!E30 -> 460850.5 | F34: =Debt!F30 -> 465791.67 | G34: =Debt!G30 -> 470744.76 | H34: =Debt!H30 -> 475707.9 | I34: =Debt!I30 -> 480679.07 | J34: =Debt!J30 -> 485656.18 | K34: =Debt!K30 -> 490637.02 | L34: =Debt!L30 -> 495619.26 | ... X34: =Debt!X30 -> 0
B35: DSCR | C35: x | E35: =IFERROR(IF(E34=0,"",E33/E34),"") -> 2.0176563 | F35: =IFERROR(IF(F34=0,"",F33/F34),"") -> 2.0282822 | G35: =IFERROR(IF(G34=0,"",G33/G34),"") -> 2.0411314 | H35: =IFERROR(IF(H34=0,"",H33/H34),"") -> 2.0541404 | I35: =IFERROR(IF(I34=0,"",I33/I34),"") -> 2.067314 | J35: =IFERROR(IF(J34=0,"",J33/J34),"") -> 1.5846505 | K35: =IFERROR(IF(K34=0,"",K33/K34),"") -> 1.5786656 | L35: =IFERROR(IF(L34=0,"",L33/L34),"") -> 1.5715564 | ... X35: =IFERROR(IF(X34=0,"",X33/X34),"")
B36: Free cash flow to equity | C36: USD | D36: =-Debt!$D$15 -> -2406084.6 | E36: =E33-E34-Debt!E36 -> 466516.86 | F36: =F33-F34-Debt!F36 -> 476488.75 | G36: =G33-G34-Debt!G36 -> 487625.6 | H36: =H33-H34-Debt!H36 -> 498977.31 | I36: =I33-I34-Debt!I36 -> 510546.97 | J36: =J33-J34-Debt!J36 -> 281448.7 | K36: =K33-K34-Debt!K36 -> 281423.67 | L36: =L33-L34-Debt!L36 -> 280783.76 | ... X36: =X33-X34-Debt!X36 -> 850374.29
B38: OPEX +20%
B39: Revenue | C39: USD | E39: =MAX(MIN(Model!E10*1,Assumptions!$D$35),Assumptions!$D$35*Assumptions!$D$36)*Model!E14*1 -> 1193766.9 | F39: =MAX(MIN(Model!F10*1,Assumptions!$D$35),Assumptions!$D$35*Assumptions!$D$36)*Model!F14*1 -> 1210945.2 | G39: =MAX(MIN(Model!G10*1,Assumptions!$D$35),Assumptions!$D$35*Assumptions!$D$36)*Model!G14*1 -> 1228370.7 | H39: =MAX(MIN(Model!H10*1,Assumptions!$D$35),Assumptions!$D$35*Assumptions!$D$36)*Model!H14*1 -> 1246046.9 | I39: =MAX(MIN(Model!I10*1,Assumptions!$D$35),Assumptions!$D$35*Assumptions!$D$36)*Model!I14*1 -> 1263977.6 | J39: =MAX(MIN(Model!J10*1,Assumptions!$D$35),Assumptions!$D$35*Assumptions!$D$36)*Model!J14*1 -> 1282166.2 | K39: =MAX(MIN(Model!K10*1,Assumptions!$D$35),Assumptions!$D$35*Assumptions!$D$36)*Model!K14*1 -> 1300616.6 | L39: =MAX(MIN(Model!L10*1,Assumptions!$D$35),Assumptions!$D$35*Assumptions!$D$36)*Model!L14*1 -> 1319332.4 | ... X39: =MAX(MIN(Model!X10*1,Assumptions!$D$35),Assumptions!$D$35*Assumptions!$D$36)*Model!X14*1 -> 1615967.8
B40: Operating costs | C40: USD | E40: =Model!E18*1.2 -> -216438.3 | F40: =Model!F18*1.2 -> -224013.64 | G40: =Model!G18*1.2 -> -231854.12 | H40: =Model!H18*1.2 -> -239969.01 | I40: =Model!I18*1.2 -> -248367.93 | J40: =Model!J18*1.2 -> -257060.8 | K40: =Model!K18*1.2 -> -266057.93 | L40: =Model!L18*1.2 -> -275369.96 | ... X40: =Model!X18*1.2 -> -416102.92
B41: EBITDA | C41: USD | E41: =E39+E40 -> 977328.57 | F41: =F39+F40 -> 986931.54 | G41: =G39+G40 -> 996516.56 | H41: =H39+H40 -> 1006077.9 | I41: =I39+I40 -> 1015609.6 | J41: =J39+J40 -> 1025105.4 | K41: =K39+K40 -> 1034558.6 | L41: =L39+L40 -> 1043962.5 | ... X41: =X39+X40 -> 1199864.9
B42: Taxation | C42: USD | E42: =IF(Model!E27=1,0,-MAX(0,E41-Debt!E29-Model!E25)*(Assumptions!$D$62+Assumptions!$D$63)) -> 0 | F42: =IF(Model!F27=1,0,-MAX(0,F41-Debt!F29-Model!F25)*(Assumptions!$D$62+Assumptions!$D$63)) -> 0 | G42: =IF(Model!G27=1,0,-MAX(0,G41-Debt!G29-Model!G25)*(Assumptions!$D$62+Assumptions!$D$63)) -> 0 | H42: =IF(Model!H27=1,0,-MAX(0,H41-Debt!H29-Model!H25)*(Assumptions!$D$62+Assumptions!$D$63)) -> 0 | I42: =IF(Model!I27=1,0,-MAX(0,I41-Debt!I29-Model!I25)*(Assumptions!$D$62+Assumptions!$D$63)) -> 0 | J42: =IF(Model!J27=1,0,-MAX(0,J41-Debt!J29-Model!J25)*(Assumptions!$D$62+Assumptions!$D$63)) -> -245713.96 | K42: =IF(Model!K27=1,0,-MAX(0,K41-Debt!K29-Model!K25)*(Assumptions!$D$62+Assumptions!$D$63)) -> -255264.62 | L42: =IF(Model!L27=1,0,-MAX(0,L41-Debt!L29-Model!L25)*(Assumptions!$D$62+Assumptions!$D$63)) -> -265566.08 | ... X42: =IF(Model!X27=1,0,-MAX(0,X41-Debt!X29-Model!X25)*(Assumptions!$D$62+Assumptions!$D$63)) -> -395955.41
B43: CFADS | C43: USD | E43: =E41+E42 -> 977328.57 | F43: =F41+F42 -> 986931.54 | G43: =G41+G42 -> 996516.56 | H43: =H41+H42 -> 1006077.9 | I43: =I41+I42 -> 1015609.6 | J43: =J41+J42 -> 779391.43 | K43: =K41+K42 -> 779294.01 | L43: =L41+L42 -> 778396.39 | ... X43: =X41+X42 -> 803909.47
B44: Debt service | C44: USD | E44: =Debt!E30 -> 460850.5 | F44: =Debt!F30 -> 465791.67 | G44: =Debt!G30 -> 470744.76 | H44: =Debt!H30 -> 475707.9 | I44: =Debt!I30 -> 480679.07 | J44: =Debt!J30 -> 485656.18 | K44: =Debt!K30 -> 490637.02 | L44: =Debt!L30 -> 495619.26 | ... X44: =Debt!X30 -> 0
B45: DSCR | C45: x | E45: =IFERROR(IF(E44=0,"",E43/E44),"") -> 2.1207063 | F45: =IFERROR(IF(F44=0,"",F43/F44),"") -> 2.1188261 | G45: =IFERROR(IF(G44=0,"",G43/G44),"") -> 2.1168936 | H45: =IFERROR(IF(H44=0,"",H43/H44),"") -> 2.1149069 | I45: =IFERROR(IF(I44=0,"",I43/I44),"") -> 2.1128642 | J45: =IFERROR(IF(J44=0,"",J43/J44),"") -> 1.6048214 | K45: =IFERROR(IF(K44=0,"",K43/K44),"") -> 1.588331 | L45: =IFERROR(IF(L44=0,"",L43/L44),"") -> 1.5705531 | ... X45: =IFERROR(IF(X44=0,"",X43/X44),"")
B46: Free cash flow to equity | C46: USD | D46: =-Debt!$D$15 -> -2406084.6 | E46: =E43-E44-Debt!E36 -> 514007.49 | F46: =F43-F44-Debt!F36 -> 518663.33 | G46: =G43-G44-Debt!G36 -> 523290.23 | H46: =H43-H44-Debt!H36 -> 527884.44 | I46: =I43-I44-Debt!I36 -> 532441.99 | J46: =J43-J44-Debt!J36 -> 291244.83 | K46: =K43-K44-Debt!K36 -> 286165.87 | L46: =L43-L44-Debt!L36 -> 280286.53 | ... X46: =X43-X44-Debt!X36 -> 803909.47
...

Sheet Dashboard
B2: CircularEnergies
B3: SUMMARY DASHBOARD
B4: Headline outputs - illustrative sample
B6: PROJECT
B7: Project | D7: Kano Agro-Industrial Solar-plus-Storage
B8: Configuration | D8: 5.0 MWp solar PV + 4.0 MWh battery storage
B9: Structure | D9: 15-year C&I PPA, take-or-pay, USD-indexed
B11: CAPITAL STRUCTURE
B12: Total project cost | D12: =Debt!$D$12 -> 6085914.6
B13: Senior debt | D13: =Debt!$D$14 -> 3679830
B14: Sponsor equity | D14: =Debt!$D$15 -> 2406084.6
B15: Effective gearing | D15: =Debt!$D$18 -> 0.604647
B17: RETURNS
B18: Project IRR (post-tax) | D18: =Returns!$D$19 -> 0.15184688
B19: Equity IRR | D19: =Returns!$D$20 -> 0.19909563 | E19: Hurdle 18.0%
B20: Equity NPV at hurdle | D20: =Returns!$D$21 -> 220586.42
B22: DEBT METRICS
B23: Minimum DSCR | D23: =Returns!$D$15 -> 1.5019476 | E23: Covenant 1.30x
B24: Average DSCR | D24: =Returns!$D$16 -> 1.8078006
B25: LLCR at close | D25: =Returns!$D$17 -> 2.1686715
B27: OPERATING METRICS
B28: Year 1 revenue | D28: =Model!E15 -> 1193766.9
B29: Year 1 EBITDA | D29: =Model!E19 -> 1013401.6
B30: Year 1 EBITDA margin | D30: =Model!E20 -> 0.84891083
B31: Installed cost per Wp | D31: =Returns!$D$26 -> 1.1151
B34: Illustrative sample prepared by CircularEnergies Ltd. Hypothetical project and counterparties. Not a live engagement and not for reliance.
